<?xml version="1.0"?>

<robot name="my_robot">

<material name="blue">
    <color rgba="0 0 0.8 1"/>
  </material>

  <material name="green">
    <color rgba="0 0.8 0 1"/>
  </material>

  <material name="orange">
    <color rgba="1 0.5 0 1"/>
  </material>

  <material name="yellow">
    <color rgba="1 1 0 1"/>
  </material>

  <link name="base_link">
    <visual>
      <geometry>
        <box size="1 1 .5"/>
      </geometry>
      <origin xyz="0 0 0" rpy="0 0 0"/>
      <material name="blue"/>
    </visual>
  </link>

  <link name="second_link">
    <visual>
      <geometry>
        <cylinder radius="0.125" length=".250"/>
      </geometry>
      <origin xyz="0 0 -0.125" rpy="0 0 0"/>
      <material name="green"/>
    </visual>
  </link>

  <link name="third_link">
    <visual>
      <geometry>
        <cylinder radius="0.125" length="0.25"/>
      </geometry>
      <origin xyz="0 0.125 0" rpy="0 0 0"/>
      <material name="blue"/>
      </visual>
       <visual>
      <geometry>
        <box size="0.25 0.5 0.25"/>
      </geometry>
      <origin xyz="0 .5 0" rpy="0 0 0"/>
      <material name="green"/>
    </visual>
  </link>

  <link name="fourth_link">
    <visual>
      <geometry>
        <cylinder radius="0.125" length=".250"/>
      </geometry>
      <origin xyz="0 0.125 0" rpy="0 0 0"/>
      <material name="orange"/>
      </visual>
      <visual>
      <geometry>
        <box size="1 0.25 0.25"/>
      </geometry>
      <origin xyz="0.625 0.125 0" rpy="0 0 0"/>
      <material name="green"/>
    </visual>
    </link>
 <link name="fifth_link">
    <visual>
      <geometry>
        <cylinder radius="0.125" length=".250"/>
      </geometry>
      <origin xyz="0 0 0" rpy="0 0 0"/>
      <material name="yellow"/>
      </visual>
      <visual>
      <geometry>
        <box size="0.25 0.25 0.5"/>
      </geometry>
      <origin xyz="0 0 0.375" rpy="0 0 0"/>
      <material name="green"/>
    </visual>
    </link>
  <link name="sixth_link">
    <visual>
      <geometry>
        <cylinder radius="0.125" length=".250"/>
      </geometry>
      <origin xyz="0 0 0" rpy="0 0 0"/>
      <material name="blue"/>
      </visual>
      <visual>
      <geometry>
        <box size="0.5 0.25 0.25"/>
      </geometry>
      <origin xyz="0.375 0 0" rpy="0 0 0"/>
      <material name="green"/>
    </visual>
    </link>
  <link name="seven_link">
    <visual>
      <geometry>
        <cylinder radius="0.125" length=".250"/>
      </geometry>
      <origin xyz="0 0 0.125" rpy="0 0 0"/>
      <material name="green"/>
      </visual>
      <visual>
      <geometry>
        <box size="0.25 0.25 0.5"/>
      </geometry>
      <origin xyz="0 0 0.5" rpy="0 0 0"/>
      <material name="green"/>
    </visual>
    </link>
    <link name="tool_link">
    <visual>
      <geometry>
        <cylinder radius="0.125" length=".250"/>
      </geometry>
      <origin xyz="0 0 0.125" rpy="0 0 0"/>
      <material name="orange"/>
      </visual>
    
    </link>
    
  <joint name="first_joint" type="revolute">
    <parent link="base_link"/>
    <child link="second_link"/>
    <origin xyz="0 0 .25" rpy="-3.1416 0 0"/>
    <axis xyz="0 0 1"/>
    <limit lower="-1.57" upper="1.57" effort="10" velocity="1"/>
  </joint>
  
    <joint name="second_joint" type="revolute">
    <parent link="second_link"/>
    <child link="third_link"/>
    <origin xyz="0 0 -0.250" rpy="-1.57 0 -3.1416"/>
    <axis xyz="0 0 1"/>
    <limit lower="-1.57" upper="1.57" effort="10" velocity="1"/>
  </joint>
     <joint name="third_joint" type="revolute">
    <parent link="third_link"/>
    <child link="fourth_link"/>
    <origin xyz="0 0.75 0" rpy="-3.1416 0 -3.1416"/>
    <axis xyz="0 0 1"/>
    <limit lower="-1.57" upper="1.57" effort="10" velocity="1"/>
  </joint>
      <joint name="fourth_joint" type="revolute">
      <parent link="fourth_link"/>
      <child link="fifth_link"/>
      <origin xyz="1.250 0.125 0" rpy=" 0 -1.57 -3.1416"/>
      <axis xyz="0 0 1"/>
      <limit lower="-1.57" upper="1.57" effort="10" velocity="1"/>  
      </joint>
      <joint name="fifth_joint" type="revolute">
      <parent link="fifth_link"/>
      <child link="sixth_link"/>
      <origin xyz="0 0 0.750" rpy="0 -1.57 -3.1416"/>
      <axis xyz="0 0 1"/>
      <limit lower="-1.57" upper="1.57" effort="10" velocity="1"/>
  </joint>
  <joint name="sixth_joint" type="revolute">
      <parent link="sixth_link"/>
      <child link="seven_link"/>
      <origin xyz="0.625 0 0" rpy="0 -1.57 -3.1416"/>
      <axis xyz="0 0 1"/>
      <limit lower="-1.57" upper="1.57" effort="10" velocity="1"/>  
      </joint>
<joint name="tool_joint" type="revolute">
      <parent link="seven_link"/>
      <child link="tool_link"/>
      <origin xyz="0 0 0.750" rpy="0 0 0"/>
      <axis xyz="0 0 1"/>
      <limit lower="-1.57" upper="1.57" effort="10" velocity="1"/>  
      </joint>
  
</robot>