<?xml version="1.0"?>

<robot name="my_robot" >
    <link name="base_link">
        <visual>
            <geometry>
                <box size="0.5 0.5 0.5"/>
            </geometry>
            <origin xyz="0 0 0" rpy="0 0 0"/>
            <material name="blue">
                <color rgba="0 0 1 1"/>
            </material>
        </visual>
    </link>

    <link name="support_link">
        <visual>
            <geometry>
                <cylinder length="0.25" radius="0.05"/>
            </geometry>
            <origin xyz="0 0 0.125" rpy="0 0 0"/>
            <material name="gray">
                <color rgba="0.5 0.5 0.5 1"/>
            </material>
        </visual>
    </link>

    <link name="arm1_link">
    <visual>
        <geometry>
            <cylinder length="0.5" radius="0.05"/>
        </geometry>
        <origin xyz="0.25 0 0" rpy="0 1.75 0"/>
        <material name="red">
            <color rgba="1 0 0 1"/>
        </material>
        </visual>
    </link>

    <link name="arm2_link">
        <visual>
            <geometry>
                <cylinder length="0.25" radius="0.05"/>
            </geometry>
            <origin xyz="0 0 0.05" rpy="0 0 0"/>
            <material name="green">
                <color rgba="0 1 0 1"/>
            </material>
        </visual>
    </link>

    <link name="arm3_link">
        <visual>
            <geometry>
                <cylinder length="0.5" radius="0.05"/>
            </geometry>
            <origin xyz="0 0 0.0625" rpy="0 1.57 0"/>
            <material name="yellow">
                <color rgba="1 1 0 1"/>
            </material>
        </visual>
    </link>




    <joint name="joint1" type="fixed">
        <origin xyz="0 0 0.25" rpy="0 0 0"/>
        <parent link="base_link"/>
        <child link="support_link"/>
        <axis xyz="0 0 1"/>
        <limit lower="-1.57" upper="1.57" effort="100" velocity="100"/>
    </joint>

    <joint name="joint2" type="revolute">
        <origin xyz="0 0 0.25" rpy="0 0 0"/>
        <parent link="support_link"/>
        <child link="arm1_link"/>
        <axis xyz="0 -1 0"/>
        <limit lower="-1.57" upper="1.57" effort="100" velocity="100"/>
    </joint>

    <joint name="joint3" type="fixed">
        <origin xyz="0.5 0 0" rpy="0 0 0"/>
        <parent link="arm1_link"/>
        <child link="arm2_link"/>
        <axis xyz="0 0 1"/>
        <limit lower="-1.57" upper="1.57" effort="100" velocity="100"/>
    </joint>

    <joint name="joint4" type="prismatic">
        <origin xyz="0 0 0.15" rpy="0 0 0"/>
        <parent link="arm2_link"/>
        <child link="arm3_link"/>
        <axis xyz="1 0 0"/>
        <limit lower="-1.57" upper="1.57" effort="100" velocity="100"/>
    </joint>

</robot>